Workbook

Sheet Income Statement
A1: APPLE INC. — INCOME STATEMENT ($ in millions)
A2: Line Item | B2: FY 2024 | C2: FY 2023 | D2: Source / Note
A3: NET SALES / REVENUE
A4: Products | B4: 294866 | C4: 298085 | D4: Source: Apple 10-K FY2024, p.31
A5: Services | B5: 96169 | C5: 85200 | D5: Source: Apple 10-K FY2024, p.31
A6: Total Net Sales | B6: =B4+B5 -> 391035 | C6: =C4+C5 -> 383285 | D6: =sum of above
A8: COST OF SALES
A9: Products | B9: 210352 | C9: 210981 | D9: Source: Apple 10-K FY2024, p.31
A10: Services | B10: 24910 | C10: 24855 | D10: Source: Apple 10-K FY2024, p.31
A11: Total Cost of Sales | B11: =B9+B10 -> 235262 | C11: =C9+C10 -> 235836 | D11: =sum of above
A13: Gross Margin | B13: =B6-B11 -> 155773 | C13: =C6-C11 -> 147449 | D13: =total revenue - total cogs
A15: OPERATING EXPENSES
A16: R&D | B16: 31370 | C16: 29915 | D16: Source: Apple 10-K FY2024, p.31
A17: SG&A | B17: 26097 | C17: 24932 | D17: Source: Apple 10-K FY2024, p.31
A18: Total Operating Expenses | B18: =B16+B17 -> 57467 | C18: =C16+C17 -> 54847 | D18: =sum of above
A20: Operating Income (EBIT) | B20: =B13-B18 -> 98306 | C20: =C13-C18 -> 92602 | D20: =gross margin - opex
A22: OTHER INCOME / (EXPENSE)
A23: Interest & Dividend Income | B23: 3764 | C23: 3750 | D23: Source: Apple 10-K FY2024, p.31
A24: Interest Expense | B24: -3930 | C24: -3933 | D24: Source: Apple 10-K FY2024, p.31
A25: Other Income/(Expense), net | B25: 269 | C25: -565 | D25: Source: Apple 10-K FY2024, p.31
A26: Total Other Income/(Expense) | B26: =B23+B24+B25 -> 103 | C26: =C23+C24+C25 -> -748 | D26: =sum of above
A28: Income Before Taxes (EBT) | B28: =B20+B26 -> 98409 | C28: =C20+C26 -> 91854 | D28: =ebit + other income
A29: Provision for Income Taxes | B29: 29749 | C29: 29749 | D29: Source: Apple 10-K FY2024, p.31
A31: NET INCOME | B31: =B28-B29 -> 68660 | C31: =C28-C29 -> 62105 | D31: =ebt - taxes
A33: Memo: EBITDA | B33: =B20+B34 -> 109751 | C33: =C20+C34 -> 104121 | D33: =ebit + d&a (d&a from cfs)
A34: Memo: Depreciation & Amortization | B34: 11445 | C34: 11519 | D34: Source: Apple 10-K FY2024, CFS
A35: Memo: Effective Tax Rate | B35: =B29/B28 -> 0.30229959 | C35: =C29/C28 -> 0.32387267 | D35: =taxes / ebt
A36: Memo: Shares Outstanding (mm) | B36: 15115 | C36: 15813 | D36: Source: Apple 10-K FY2024 (diluted)
A37: Memo: EPS (Diluted) | B37: =B31/B36 -> 4.5425074 | C37: =C31/C36 -> 3.9274647 | D37: =net income / shares
A40: COLOR LEGEND
A41: Yellow → Hardcoded Input (blue text)
A42: Green → Formula / Calculated
A43: Gray → Label / Section Header
A44: Blue → Assumption

Sheet Balance Sheet
A1: APPLE INC. — BALANCE SHEET ($ in millions)
A2: Line Item | B2: FY 2024 (Sep 28, 2024) | C2: FY 2023 (Sep 30, 2023) | D2: Source / Note
A3: CURRENT ASSETS
A4: Cash & Cash Equivalents | B4: 29943 | C4: 29965 | D4: Source: Apple 10-K FY2024, p.48
A5: Marketable Securities (current) | B5: 35228 | C5: 31590 | D5: Source: Apple 10-K FY2024, p.48
A6: Accounts Receivable, net | B6: 33410 | C6: 29508 | D6: Source: Apple 10-K FY2024, p.48
A7: Inventories | B7: 7286 | C7: 6331 | D7: Source: Apple 10-K FY2024, p.48
A8: Other Current Assets | B8: 14695 | C8: 14695 | D8: Source: Apple 10-K FY2024, p.48
A9: Total Current Assets | B9: =B4+B5+B6+B7+B8 -> 120562 | C9: =C4+C5+C6+C7+C8 -> 112089 | D9: =sum above
A11: NON-CURRENT ASSETS
A12: Marketable Securities (non-current) | B12: 91479 | C12: 100544 | D12: Source: Apple 10-K FY2024, p.48
A13: Property, Plant & Equipment, net | B13: 45680 | C13: 43715 | D13: Source: Apple 10-K FY2024, p.48
A14: Other Non-Current Assets | B14: 68011 | C14: 64758 | D14: Source: Apple 10-K FY2024, p.48
A15: Total Non-Current Assets | B15: =B12+B13+B14 -> 205170 | C15: =C12+C13+C14 -> 209017 | D15: =sum above
A17: TOTAL ASSETS | B17: =B9+B15 -> 325732 | C17: =C9+C15 -> 321106 | D17: =current + non-current assets
A19: CURRENT LIABILITIES
A20: Accounts Payable | B20: 68960 | C20: 62611 | D20: Source: Apple 10-K FY2024, p.48
A21: Other Current Liabilities | B21: 78304 | C21: 58563 | D21: Source: Apple 10-K FY2024, p.48
A22: Term Debt (current) | B22: 10912 | C22: 9822 | D22: Source: Apple 10-K FY2024, p.48
A23: Total Current Liabilities | B23: =B20+B21+B22 -> 158176 | C23: =C20+C21+C22 -> 130996 | D23: =sum above
A25: NON-CURRENT LIABILITIES
A26: Term Debt (non-current) | B26: 85750 | C26: 95281 | D26: Source: Apple 10-K FY2024, p.48
A27: Other Non-Current Liabilities | B27: 44614 | C27: 49848 | D27: Source: Apple 10-K FY2024, p.48
A28: Total Non-Current Liabilities | B28: =B26+B27 -> 130364 | C28: =C26+C27 -> 145129 | D28: =sum above
A30: TOTAL LIABILITIES | B30: =B23+B28 -> 288540 | C30: =C23+C28 -> 276125 | D30: =current + non-current liabilities
A32: SHAREHOLDERS' EQUITY
A33: Common Stock & Additional Paid-in Capital | B33: 83276 | C33: 73812 | D33: Source: Apple 10-K FY2024, p.48
A34: Retained Earnings (Deficit) | B34: -19154 | C34: -214 | D34: Source: Apple 10-K FY2024, p.48
A35: Accumulated Other Comprehensive Income/(Loss) | B35: -7134 | C35: -11452 | D35: Source: Apple 10-K FY2024, p.48
A36: Total Shareholders' Equity | B36: =B33+B34+B35 -> 56988 | C36: =C33+C34+C35 -> 62146 | D36: =sum above
A38: TOTAL LIABILITIES & EQUITY | B38: =B30+B36 -> 345528 | C38: =C30+C36 -> 338271 | D38: =total liabilities + total equity

Sheet Cash Flow Statement
A1: APPLE INC. — CASH FLOW STATEMENT ($ in millions)
A2: Line Item | B2: FY 2024 | C2: FY 2023 | D2: Source / Note
A3: OPERATING ACTIVITIES
A4: Net Income | B4: ='Income Statement'!B31 -> 68660 | C4: ='Income Statement'!C31 -> 62105 | D4: =link from is
A5: Depreciation & Amortization | B5: 11445 | C5: 11519 | D5: Source: Apple 10-K FY2024, p.51
A6: Share-Based Compensation | B6: 11688 | C6: 10833 | D6: Source: Apple 10-K FY2024, p.51
A7: Changes in Working Capital & Other | B7: -3455 | C7: -1062 | D7: Source: Apple 10-K FY2024, p.51
A8: Net Cash from Operating Activities | B8: 118254 | C8: 110543 | D8: Source: Apple 10-K FY2024, p.51
A10: INVESTING ACTIVITIES
A11: Capital Expenditures (CapEx) | B11: -9447 | C11: -10959 | D11: Source: Apple 10-K FY2024, p.51
A12: Purchases of Marketable Securities | B12: -48656 | C12: -29513 | D12: Source: Apple 10-K FY2024, p.51
A13: Proceeds from Maturities of Securities | B13: 62346 | C13: 39686 | D13: Source: Apple 10-K FY2024, p.51
A14: Other Investing Activities | B14: -1308 | C14: -1337 | D14: Source: Apple 10-K FY2024, p.51
A15: Net Cash from Investing Activities | B15: =B11+B12+B13+B14 -> 2935 | C15: =C11+C12+C13+C14 -> -2123 | D15: =sum above
A17: FINANCING ACTIVITIES
A18: Repurchase of Common Stock | B18: -94949 | C18: -77550 | D18: Source: Apple 10-K FY2024, p.51
A19: Dividends Paid | B19: -15234 | C19: -15025 | D19: Source: Apple 10-K FY2024, p.51
A20: Proceeds from Debt Issuance | B20: 5998 | C20: 5228 | D20: Source: Apple 10-K FY2024, p.51
A21: Repayment of Debt | B21: -9958 | C21: -11151 | D21: Source: Apple 10-K FY2024, p.51
A22: Other Financing Activities | B22: -1384 | C22: -3430 | D22: Source: Apple 10-K FY2024, p.51
A23: Net Cash from Financing Activities | B23: =B18+B19+B20+B21+B22 -> -115527 | C23: =C18+C19+C20+C21+C22 -> -101928 | D23: =sum above
A25: NET CHANGE IN CASH | B25: =B8+B15+B23 -> 5662 | C25: =C8+C15+C23 -> 6492 | D25: =sum of all net cash flows
A26: Beginning Cash Balance | B26: 29965 | C26: 24977 | D26: Source: Apple 10-K FY2024, p.51
A27: Ending Cash Balance | B27: =B26+B25 -> 35627 | C27: =C26+C25 -> 31469 | D27: =beginning + net change
A29: Memo: Free Cash Flow (FCF) | B29: =B8+B11 -> 108807 | C29: =C8+C11 -> 99584 | D29: =operating cf - capex
A30: Memo: FCF Yield | B30: See Ratios Tab | C30: See Ratios Tab | D30: =fcf / market cap (from ratios tab)

Sheet Ratios
A1: APPLE INC. — ACCOUNTING RATIO ANALYSIS (FY 2024)
A2: SECTION A — INPUTS
A3: Named Range | B3: Value | C3: Units | D3: Description | E3: Source Cell
A4: ── MARKET / ANALYST INPUTS ──
A5: mkt_share_price | B5: 152.37 | C5: $ | D5: Share price as of Sep 27 2024 close | E5: Source: Yahoo Finance, Sep 27 2024
A6: mkt_shares_out | B6: ='Income Statement'!B36 -> 15115 | C6: mm | D6: Diluted shares outstanding | E6: IS!B36
A7: mkt_cap | B7: =B5*B6 -> 2303072.5 | C7: $mm | D7: =share_price × shares_out
A8: cost_of_capital | B8: 0.09 | C8: % | D8: WACC estimate (analyst assumption) | E8: Source: Damodaran WACC dataset
A9: tax_rate | B9: ='Income Statement'!B35 -> 0.30229959 | C9: % | D9: =effective tax rate from is
A11: ── START-OF-YEAR (FY2023) ──
A12: startYear_equity | B12: ='Balance Sheet'!C36 -> 62146 | C12: $mm | D12: FY2023 Total Equity | E12: BS!C36
A13: startYear_inventories | B13: ='Balance Sheet'!C7 -> 6331 | C13: $mm | D13: FY2023 Inventories | E13: BS!C7
A14: startYear_receivables | B14: ='Balance Sheet'!C6 -> 29508 | C14: $mm | D14: FY2023 Accounts Receivable | E14: BS!C6
A15: startYear_assets_total | B15: ='Balance Sheet'!C17 -> 321106 | C15: $mm | D15: FY2023 Total Assets | E15: BS!C17
A16: startYear_total_cap | B16: ='Balance Sheet'!C36+'Balance Sheet'!C26 -> 157427 | C16: $mm | D16: FY2023 LT Debt + Equity | E16: BS computation
A18: ── CURRENT YEAR (FY2024) ──
A19: INC_net | B19: ='Income Statement'!B31 -> 68660 | C19: $mm | D19: Net Income | E19: IS!B31
A20: INC_ebit | B20: ='Income Statement'!B20 -> 98306 | C20: $mm | D20: EBIT | E20: IS!B20
A21: INC_ebitda | B21: ='Income Statement'!B33 -> 109751 | C21: $mm | D21: EBITDA | E21: IS!B33
A22: INC_revenue | B22: ='Income Statement'!B6 -> 391035 | C22: $mm | D22: Total Net Sales | E22: IS!B6
A23: INC_gross_margin | B23: ='Income Statement'!B13 -> 155773 | C23: $mm | D23: Gross Profit | E23: IS!B13
A24: INC_interest_exp | B24: =ABS('Income Statement'!B24) -> 3930 | C24: $mm | D24: Interest Expense (abs) | E24: IS!B24
A25: INC_taxes | B25: ='Income Statement'!B29 -> 29749 | C25: $mm | D25: Income Tax Provision | E25: IS!B29
A26: currentYear_equity | B26: ='Balance Sheet'!B36 -> 56988 | C26: $mm | D26: FY2024 Total Equity | E26: BS!B36
A27: currentYear_cash | B27: ='Balance Sheet'!B4 -> 29943 | C27: $mm | D27: FY2024 Cash | E27: BS!B4
A28: currentYear_assets_CA | B28: ='Balance Sheet'!B9 -> 120562 | C28: $mm | D28: FY2024 Current Assets | E28: BS!B9
A29: currentYear_liab_CL | B29: ='Balance Sheet'!B23 -> 158176 | C29: $mm | D29: FY2024 Current Liabilities | E29: BS!B23
A30: currentYear_LT_debt | B30: ='Balance Sheet'!B26 -> 85750 | C30: $mm | D30: FY2024 LT Debt (non-current) | E30: BS!B26
A31: currentYear_assets_total | B31: ='Balance Sheet'!B17 -> 325732 | C31: $mm | D31: FY2024 Total Assets | E31: BS!B17
A32: currentYear_total_cap | B32: ='Balance Sheet'!B36+'Balance Sheet'!B26 -> 142738 | C32: $mm | D32: FY2024 LT Debt + Equity | E32: BS computation
A33: currentYear_total_liab | B33: ='Balance Sheet'!B30 -> 288540 | C33: $mm | D33: FY2024 Total Liabilities | E33: BS!B30
A34: currentYear_NWC | B34: =B28-B29 -> -37614 | C34: $mm | D34: =ca - cl
A35: currentYear_inventories | B35: ='Balance Sheet'!B7 -> 7286 | C35: $mm | D35: FY2024 Inventories | E35: BS!B7
A36: currentYear_receivables | B36: ='Balance Sheet'!B6 -> 33410 | C36: $mm | D36: FY2024 Accounts Receivable | E36: BS!B6
A37: INC_daily_sales | B37: =B22/365 -> 1071.3288 | C37: $mm | D37: =revenue / 365
A38: ATOI | B38: =B20*(1-B9) -> 68588.137 | C38: $mm | D38: After-Tax Operating Income = EBIT×(1−tax_rate)
A40: ── AVERAGES ──
A41: avg_equity | B41: =(B12+B26)/2 -> 59567 | C41: $mm | D41: =(startyear + currentyear equity)/2
A42: avg_assets_total | B42: =(B15+B31)/2 -> 323419 | C42: $mm | D42: =(startyear + currentyear assets)/2
A43: avg_total_cap | B43: =(B16+B32)/2 -> 150082.5 | C43: $mm | D43: =(startyear + currentyear total cap)/2
...

Sheet Notes
A1: NOTES, ASSUMPTIONS & DATA SOURCES
A2: COMPANY | B2: Apple Inc. (NASDAQ: AAPL)
A3: FISCAL YEAR | B3: FY2024 ends September 28, 2024; FY2023 ends September 30, 2023
A4: CURRENCY | B4: All figures in USD millions ($mm) unless otherwise noted
A6: DATA SOURCES
A7: Primary | B7: Apple Inc. Form 10-K FY2024 filed with SEC EDGAR (CIK: 0000320193)
A8: URL | B8: https://investor.apple.com/sec-filings/annual-reports
A9: Cross-check | B9: Yahoo Finance (finance.yahoo.com) for share price and market data
A10: WACC | B10: Damodaran NYU dataset; tech sector WACC estimate of 9.0%
A12: KEY ASSUMPTIONS
A13: Share Price | B13: $152.37 — closing price Sep 27, 2024 (day before fiscal year-end)
A14: Shares | B14: Diluted weighted-average shares from 10-K used for EPS and market cap
A15: WACC / Cost of Capital | B15: 9.0% (analyst assumption; sensitivity analysis recommended)
A16: Start-of-Year | B16: FY2023 Balance Sheet figures used as start-of-year for all ratios
A17: D&A | B17: From Cash Flow Statement (indirect method operating section)
A18: Inventories | B18: Apple carries very lean inventory (~7 days) given fabless model
A19: Negative Equity | B19: Apple's equity is near zero / slightly negative due to massive buybacks; leverage ratios should be interpreted carefully in this context
A21: RATIO FORMULA NOTES
A22: ATOI | B22: After-Tax Operating Income = EBIT × (1 − Effective Tax Rate)
A23: EVA | B23: EVA = ATOI − (WACC × Total Capitalization); positive = economic value creation
A24: MVA | B24: MVA = Market Cap − Book Equity; measures value created above book investment
A25: Du Pont ROA | B25: Profit Margin × Asset Turnover; should reconcile to direct ROA
A26: Du Pont ROE | B26: Du Pont ROA × (Assets/Equity); should reconcile to direct ROE
A27: Debt-Equity | B27: Apple's negative or near-zero equity makes this ratio extreme; supplement with Total Debt Ratio for context
A29: LIMITATIONS
A30: Single Year | B30: Analysis covers FY2024 and one prior year; multi-year trend recommended
A31: Peer Comparison | B31: No competitor benchmarking included; add Alphabet / Microsoft for context
A32: Segment Detail | B32: Ratios computed on consolidated basis; segment-level margins differ materially
